Workbook

Sheet Business
A1: Phase | B1: Task | C1: Subtask | D1: Hours Needed | E1: Owner | F1: Status
A2: 1. Research and Planning | B2: Research about Polymarket | C2: Study on Polymarket as decentralized platform and gap identification | D2: 60 | E2: B1, B2
C3: Use case on how prediction market outperform traditional risk transfer methods | D3: 60 | E3: B1, B2
B4: Define Project Scope | C4: Prototype operation model design for binary predictive market | D4: 30 | E4: B1,B2
C5: Estimation on SDLC | D5: 20 | E5: T1
B6: Identify Target Audience | C6: User identification in politics, sports, crypto events, etc., which are niche opportunities in underserved markets | D6: 25 | E6: B1,B2
C7: Institutional application exploration | D7: 25 | E7: B1,B2
B8: Competitior Analysis | C8: Study about Polymarket, Kalshi, Augur for multiple features, including yes/no betting, liquidity pools, resolution mechanism | D8: 60 | E8: B1,B2,H
B9: Legal Requirement Analysis | C9: Regulation research, including but not limited to gambling law, KYC/AML | D9: 70 | E9: B1,B2
B10: Technical Research | C10: Study on Blockchain | D10: 50 | E10: B1,B2
C11: Study on Smart Contract | D11: 50 | E11: B1,B2
C12: Study on security measures | D12: 50 | E12: B1,B2,T1
B13: Cost Analysis | C13: Budget for technical development | D13: 20 | E13: B2
A14: 2. Report Writing | B14: Report Writing | C14: Summarize the research | D14: 160 | E14: B1,B2,H,T1,T2
C15: Provide insights on the risk transfer model of prediction market | D15: 160 | E15: B1,B2,H,T1,T2
C16: Report checking and finalization | D16: 20 | E16: B1,B2
A17: 3. Deployment and Launch | B17: Market the Platform | C17: Promote on social media | D17: 20 | E17: B1,B2
C18: Build community via Discord, Twitter and forums | D18: 20 | E18: B1,B2
C19: Total | D19: =SUM(D2:D18) -> 900
A20: Business Role 1 | B20: Researcher, UI/UX Designer, End User, Business Analyst, Tester | C20: =SUMPRODUCT( (ISNUMBER(SEARCH("B1",$E$2:$E$18)))* ($D$2:$D$18/(LEN($E$2:$E$18)-LEN(SUBSTITUTE($E$2:$E$18,",",""))+1))) -> 315.66667
A21: Business Role 2 | B21: Researcher, Project Manager, End User, Business Analyst, Tester | C21: =SUMPRODUCT( (ISNUMBER(SEARCH("B2",$E$2:$E$18)))* ($D$2:$D$18/(LEN($E$2:$E$18)-LEN(SUBSTITUTE($E$2:$E$18,",",""))+1))) -> 335.66667
A22: Hybrid Role | B22: Researcher, Business Analyst, Developer, Tester | C22: =SUMPRODUCT( (ISNUMBER(SEARCH("H",$E$2:$E$18)))* ($D$2:$D$18/(LEN($E$2:$E$18)-LEN(SUBSTITUTE($E$2:$E$18,",",""))+1))) -> 84
A23: Technical Role 1 | B23: Project Manager, Business Analyst, Tester, Developer | C23: =SUMPRODUCT( (ISNUMBER(SEARCH("T1",$E$2:$E$18)))* ($D$2:$D$18/(LEN($E$2:$E$18)-LEN(SUBSTITUTE($E$2:$E$18,",",""))+1))) -> 100.66667
A24: Technical Role 2 | B24: Solution Architect, Full Stack Developer, Tester | C24: =SUMPRODUCT( (ISNUMBER(SEARCH("T2",$E$2:$E$18)))* ($D$2:$D$18/(LEN($E$2:$E$18)-LEN(SUBSTITUTE($E$2:$E$18,",",""))+1))) -> 64

Sheet Technical
A1: Phase | B1: Task | C1: Subtask | D1: Hours Needed | E1: Owner | F1: Status
A2: 0. Preparation | B2: Study | C2: Study Blockchain, including Etherum | D2: 90 | E2: Developer (T1,T2, H) | F2: In Progress
C3: Study Solidity for Smart Contract | D3: 90 | E3: Developer (T1,T2, H) | F3: To be started
C4: Study Chainlink, UMA for real-world data fetching to resolve market | D4: 90 | E4: Developer (T1,T2, H) | F4: To be started
B5: Tools | C5: Install all relevant tools and study the relevant frontend and backend programming language | D5: 30 | E5: Developer (T1,T2, H) | F5: Completed
A6: 1. Planning | B6: Scope Definition | D6: 20 | E6: Business Analyst (T1, H), End User (B1, B2) | F6: In Progress
B7: Requirement Gathering | C7: Features to be developed | D7: 20 | E7: Business Analyst (T1, H), Developer (T2) | F7: To be started
B8: Waterfall Project Planning and Management | C8: Timeline Establishment | D8: 15 | E8: Project Manager (T1, B2) | F8: In Progress
C9: Resources Allocation | D9: 15 | E9: Project Manager (T1, B2) | F9: In Progress
A10: 2. Analysis | B10: User Story | C10: User Story Creation | D10: 20 | E10: Business Analyst (B1,B2,T1, H) | F10: To be started
C11: User Story Grooming | D11: 20 | E11: Business Analyst (B1,B2,T1, H), Developer (T2) | F11: To be started
A12: 3. Design | B12: High-level Architecture Design | D12: 15 | E12: Solution Architect (T2) | F12: To be started
B13: Technical Solution Design | D13: 15 | E13: Solution Architect (T2) | F13: To be started
B14: UI/UX Design | C14: Figma Prototype | D14: 30 | E14: Designer (B1) | F14: To be started
A15: 4. Implementation | B15: Web development for reporting | D15: 30 | E15: Developer (T1,T2) | F15: To be started
B16: Backend development for prototype | C16: Integration with Blockchain | D16: 20 | E16: Developer (T1,T2,H) | F16: To be started
C17: Decentralize file storage development through IPFS | D17: 25 | E17: Developer (T1,T2,H) | F17: To be started
B18: Order Management Lifecycle Implementation | C18: Hybrid Central Limit Order Book (CLOB) for off-chaim matching and on-chain execution | D18: 30 | E18: Developer (T1,T2,H) | F18: To be started
B19: Smart contract development | C19: Contract creation with Gnosis Conditional Token Framework for core logic | D19: 30 | E19: Developer (T1,T2,H) | F19: To be started
C20: Create Solidity contract where users define events | D20: 40 | E20: Developer (T1,T2,H) | F20: To be started
C21: Function implementation for buying/selling shares using ERC-1155 tokens, collateralized by USDC | D21: 50 | E21: Developer (T1,T2,H) | F21: To be started
B22: Web development for prototype | C22: React app creation | D22: 25 | E22: Developer (T1,T2,H) | F22: To be started
C23: Responsive application | D23: 8 | E23: Developer (T1,T2) | F23: To be started
C24: Integration with Backend through user sessions or API calls | D24: 50 | E24: Developer (T1, T2) | F24: To be started
C25: Integration with Automated Market Makers (AMM) for dynamic pricing and liquidity | D25: 60 | E25: Developer (T2) | F25: To be started
B26: MetaMask wallet setup for getting testnet ETH from faucets for testing phase | D26: 25 | E26: Developer (T2) | F26: To be started
A27: 5. Testing and Integration | B27: Test Case Writing | D27: 20 | E27: Tester (T1, H) | F27: To be started
B28: Test Case Review | D28: 10 | E28: Tester (T1, H) | F28: To be started
B29: Unit Testing | C29: Testing the modules individually with Mocha/Chai and Ganache for local blockchain simulation | D29: 40 | E29: Developer (T2) | F29: To be started
B30: Integration Testing | C30: Testing on the interaction between individual componenet | D30: 55 | E30: Tester (T1, H) | F30: To be started
B31: End-to-End System Integration Testing (E2E SIT) | C31: Testing E2E functionality on Polyhon/ Ethereum Testnet | D31: 55 | E31: Tester (T1, H) | F31: To be started
B32: User Acceptance Test (UAT) | C32: End user testing on Polygon/ Ethereum Testnet | D32: 55 | E32: End User (B1, B2) | F32: To be started
B33: Performance Testing | C33: Evaluate the speed, responsiveness and stability of the prototype in handling high volume trading | D33: 25 | E33: Tester (T1,H) | F33: To be started
B34: Sanity Test | C34: Testing on specific bug fix/ minor change of work | D34: 40 | E34: Business Analyst (B1,H) | F34: To be started
B35: Regression Test | C35: Re-runs of the critical test cases to ensure code changes does not affect any existing functionality | D35: 40 | E35: Tester (B1,B2,T1, H) | F35: To be started
A36: 6. Deployment | B36: Beta-Testing | D36: 30 | E36: End User (B1, B2) | F36: To be started
B37: Pilot Launch | D37: 8 | E37: Business Analyst (T1, H), Developer (T2), End User (B1, B2) | F37: To be started
A38: 7. Maintenance | D38: 0 | F38: To be started
C39: Total | D39: =SUM(D2:D38) -> 1241
A40: Business Role 1 | B40: Researcher, UI/UX Designer, End User, Business Analyst, Tester | C40: =SUMPRODUCT( (ISNUMBER(SEARCH("B1",$E$2:$E$37)))* ($D$2:$D$37/(LEN($E$2:$E$37)-LEN(SUBSTITUTE($E$2:$E$37,",",""))+1))) -> 118.1
...

Sheet Total
A1: Role | B1: Responsibility | C1: Business Hours | D1: Techincal Hours | E1: Total
A2: Business Role 1 | B2: Researcher, UI/UX Designer, End User, Business Analyst, Tester | C2: =Business!C20 -> 315.66667 | D2: =Technical!C40 -> 118.1 | E2: =SUM(C2:D2) -> 433.76667
A3: Business Role 2 | B3: Researcher, Project Manager, End User, Business Analyst, Tester | C3: =Business!C21 -> 335.66667 | D3: =Technical!C41 -> 83.1 | E3: =SUM(C3:D3) -> 418.76667
A4: Hybrid Role | B4: Researcher, Business Analyst, Developer, Tester | C4: =Business!C22 -> 84 | D4: =Technical!C42 -> 338.1 | E4: =SUM(C4:D4) -> 422.1
A5: Technical Role 1 | B5: Project Manager, Business Analyst, Tester, Developer | C5: =Business!C23 -> 100.66667 | D5: =Technical!C43 -> 347.1 | E5: =SUM(C5:D5) -> 447.76667
A6: Technical Role 2 | B6: Solution Architect, Full Stack Developer, Tester | C6: =Business!C24 -> 64 | D6: =Technical!C44 -> 384.6 | E6: =SUM(C6:D6) -> 448.6
